<?xml version="1.0"?>
<robot xmlns:xacro="http://www.ros.org/wiki/xacro">

    <joint name="left_wheel_joint" type="continuous">
        <parent link="base_link"/>
        <child link="left_wheel"/>
        <origin xyz="0 0.1 0.05" rpy="-${pi/2} 0 0"/>
        <axis xyz="0 0 1"/>
    </joint>

    <link name="left_wheel">
        <visual>
            <geometry><cylinder radius="0.05" length="0.04"/></geometry>
            <material name="blue"><color rgba="0 0 1 1"/></material>
        </visual>
        <collision>
            <geometry><cylinder radius="0.05" length="0.04"/></geometry>
        </collision>
        <inertial>
            <mass value="0.1"/>
            <inertia ixx="0.00007" ixy="0.0" ixz="0.0" iyy="0.00007" iyz="0.0" izz="0.00012"/>
        </inertial>
    </link>

    <joint name="right_wheel_joint" type="continuous">
        <parent link="base_link"/>
        <child link="right_wheel"/>
        <origin xyz="0 -0.1 0.05" rpy="${pi/2} 0 0"/>
        <axis xyz="0 0 -1"/>
    </joint>

    <link name="right_wheel">
        <visual>
            <geometry><cylinder radius="0.05" length="0.04"/></geometry>
            <material name="blue"><color rgba="0 0 1 1"/></material>
        </visual>
        <collision>
            <geometry><cylinder radius="0.05" length="0.04"/></geometry>
        </collision>
        <inertial>
            <mass value="0.1"/>
            <inertia ixx="0.00007" ixy="0.0" ixz="0.0" iyy="0.00007" iyz="0.0" izz="0.00012"/>
        </inertial>
    </link>

    <gazebo>
        <plugin filename="gz-sim-diff-drive-system" name="gz::sim::systems::DiffDrive">
            <left_joint>left_wheel_joint</left_joint>
            <right_joint>right_wheel_joint</right_joint>
            <wheel_separation>0.35</wheel_separation>
            <wheel_radius>0.05</wheel_radius>
            <max_linear_acceleration>1.0</max_linear_acceleration>
            <topic>cmd_vel</topic>
            <odom_topic>odom</odom_topic>
            <frame_id>odom</frame_id>
            <child_frame_id>base_link</child_frame_id>
        </plugin>
    </gazebo>

</robot>